**********HOST: https://c4ed2810-910d-43b1-b56b-1608322b4946.us-east4-0.gcp.cloud.qdrant.io:6333
2023-11-29 15:14:02.563 Uncaught app exception
Traceback (most recent call last):
  File "C:\Users\gr80m\anaconda3\envs\langchain\lib\site-packages\httpcore\_exceptions.py", line 10, in map_exceptions
    yield
  File "C:\Users\gr80m\anaconda3\envs\langchain\lib\site-packages\httpcore\_backends\sync.py", line 206, in connect_tcp
    sock = socket.create_connection(
  File "C:\Users\gr80m\anaconda3\envs\langchain\lib\socket.py", line 787, in create_connection
    for res in getaddrinfo(host, port, 0, SOCK_STREAM):
  File "C:\Users\gr80m\anaconda3\envs\langchain\lib\socket.py", line 918, in getaddrinfo
    for res in _socket.getaddrinfo(host, port, family, type, proto, flags):
socket.gaierror: [Errno 11001] getaddrinfo failed

The above exception was the direct cause of the following exception:

Traceback (most recent call last):
  File "C:\Users\gr80m\anaconda3\envs\langchain\lib\site-packages\httpx\_transports\default.py", line 66, in map_httpcore_exceptions
    yield
  File "C:\Users\gr80m\anaconda3\envs\langchain\lib\site-packages\httpx\_transports\default.py", line 228, in handle_request
    resp = self._pool.handle_request(req)
  File "C:\Users\gr80m\anaconda3\envs\langchain\lib\site-packages\httpcore\_sync\connection_pool.py", line 268, in handle_request
    raise exc
  File "C:\Users\gr80m\anaconda3\envs\langchain\lib\site-packages\httpcore\_sync\connection_pool.py", line 251, in handle_request
    response = connection.handle_request(request)
  File "C:\Users\gr80m\anaconda3\envs\langchain\lib\site-packages\httpcore\_sync\connection.py", line 99, in handle_request
    raise exc
  File "C:\Users\gr80m\anaconda3\envs\langchain\lib\site-packages\httpcore\_sync\connection.py", line 76, in handle_request
    stream = self._connect(request)
  File "C:\Users\gr80m\anaconda3\envs\langchain\lib\site-packages\httpcore\_sync\connection.py", line 124, in _connect
    stream = self._network_backend.connect_tcp(**kwargs)
  File "C:\Users\gr80m\anaconda3\envs\langchain\lib\site-packages\httpcore\_backends\sync.py", line 213, in connect_tcp
    sock.setsockopt(socket.IPPROTO_TCP, socket.TCP_NODELAY, 1)
  File "C:\Users\gr80m\anaconda3\envs\langchain\lib\contextlib.py", line 131, in __exit__
    self.gen.throw(type, value, traceback)
  File "C:\Users\gr80m\anaconda3\envs\langchain\lib\site-packages\httpcore\_exceptions.py", line 14, in map_exceptions
    raise to_exc(exc) from exc
httpcore.ConnectError: [Errno 11001] getaddrinfo failed

The above exception was the direct cause of the following exception:

Traceback (most recent call last):
  File "C:\Users\gr80m\anaconda3\envs\langchain\lib\site-packages\qdrant_client\http\api_client.py", line 101, in send_inner
    response = self._client.send(request)
  File "C:\Users\gr80m\anaconda3\envs\langchain\lib\site-packages\httpx\_client.py", line 901, in send
    response = self._send_handling_auth(
  File "C:\Users\gr80m\anaconda3\envs\langchain\lib\site-packages\httpx\_client.py", line 929, in _send_handling_auth
    response = self._send_handling_redirects(
  File "C:\Users\gr80m\anaconda3\envs\langchain\lib\site-packages\httpx\_client.py", line 966, in _send_handling_redirects
    response = self._send_single_request(request)
  File "C:\Users\gr80m\anaconda3\envs\langchain\lib\site-packages\httpx\_client.py", line 1002, in _send_single_request
    response = transport.handle_request(request)
  File "C:\Users\gr80m\anaconda3\envs\langchain\lib\site-packages\httpx\_transports\default.py", line 228, in handle_request
    resp = self._pool.handle_request(req)
  File "C:\Users\gr80m\anaconda3\envs\langchain\lib\contextlib.py", line 131, in __exit__
    self.gen.throw(type, value, traceback)
  File "C:\Users\gr80m\anaconda3\envs\langchain\lib\site-packages\httpx\_transports\default.py", line 83, in map_httpcore_exceptions
    raise mapped_exc(message) from exc
httpx.ConnectError: [Errno 11001] getaddrinfo failed

During handling of the above exception, another exception occurred:

Traceback (most recent call last):
  File "C:\Users\gr80m\anaconda3\envs\langchain\lib\site-packages\streamlit\runtime\scriptrunner\script_runner.py", line 552, in _run_script
    exec(code, module.__dict__)
  File "C:\Users\gr80m\projects\doc-reader\app.py", line 121, in <module>
    main()
  File "C:\Users\gr80m\projects\doc-reader\app.py", line 53, in main
    vectorstore = get_vectorstore(text_chunks)
  File "C:\Users\gr80m\projects\doc-reader\app.py", line 91, in get_vectorstore
    vectorstore.add_texts(text_chunks)
  File "C:\Users\gr80m\anaconda3\envs\langchain\lib\site-packages\langchain\vectorstores\qdrant.py", line 181, in add_texts
    self.client.upsert(
  File "C:\Users\gr80m\anaconda3\envs\langchain\lib\site-packages\qdrant_client\qdrant_client.py", line 805, in upsert
    return self._client.upsert(
  File "C:\Users\gr80m\anaconda3\envs\langchain\lib\site-packages\qdrant_client\qdrant_remote.py", line 1055, in upsert
    http_result = self.openapi_client.points_api.upsert_points(
  File "C:\Users\gr80m\anaconda3\envs\langchain\lib\site-packages\qdrant_client\http\api\points_api.py", line 1247, in upsert_points
    return self._build_for_upsert_points(
  File "C:\Users\gr80m\anaconda3\envs\langchain\lib\site-packages\qdrant_client\http\api\points_api.py", line 638, in _build_for_upsert_points
    return self.api_client.request(
  File "C:\Users\gr80m\anaconda3\envs\langchain\lib\site-packages\qdrant_client\http\api_client.py", line 74, in request
    return self.send(request, type_)
  File "C:\Users\gr80m\anaconda3\envs\langchain\lib\site-packages\qdrant_client\http\api_client.py", line 91, in send
    response = self.middleware(request, self.send_inner)
  File "C:\Users\gr80m\anaconda3\envs\langchain\lib\site-packages\qdrant_client\http\api_client.py", line 200, in __call__
    return call_next(request)
  File "C:\Users\gr80m\anaconda3\envs\langchain\lib\site-packages\qdrant_client\http\api_client.py", line 103, in send_inner
    raise ResponseHandlingException(e)
qdrant_client.http.exceptions.ResponseHandlingException: [Errno 11001] getaddrinfo failed